<sdf version='1.7'>
  <model name='fpr'>
    <link name="platform">
        <pose>0 0 0.7375123727775691 0 0 0</pose>
        <inertial>
            <pose>0 0 0 0 -0 0</pose>
            <mass>0.215</mass>
            <inertia>
              <ixx>5.427e-4</ixx>
              <ixy>0</ixy>
              <ixz>0</ixz>
              <iyy>5.427e-4</iyy>
              <iyz>0</iyz>
              <izz>0.001</izz>
            </inertia>
        </inertial>
        <visual name="platform_visual">
            <pose>0 0 0 0 -0 0</pose>
            <geometry>
                <mesh>
                    <scale>0.001 0.001 0.001</scale>
                    <uri>model://fpr_interaction/meshes/platform.stl</uri>
                </mesh>
            </geometry>
        </visual>
        <collision name='platform_inertia_collision'>
            <pose>0 0 0 0 0 0</pose>
            <geometry>
                <mesh>
                    <scale>0.001 0.001 0.001</scale>
                    <uri>model://fpr_interaction/meshes/platform.stl</uri>
                </mesh>
            </geometry>
        </collision>
        <visual name="tool_visual">
            <pose>0 0 0 0 0 0</pose>
            <geometry>
                <mesh>
                    <scale>0.001 0.001 0.001</scale>
                    <uri>model://fpr_interaction/meshes/tool.stl</uri>
                </mesh>
            </geometry>
        </visual>
        <collision name='tool_inertia_collision'>
            <pose>0 0 0.027 0 0 0</pose>
            <geometry>
                <cylinder>
                    <radius>0.0022</radius>
                    <length>0.02</length>
                </cylinder>
            </geometry>
        </collision>
        <collision name='tool_inertia_collision_2'>
            <pose>0 0 0.05 0 0 0</pose>
            <geometry>
                <cylinder>
                    <radius>0.02</radius>
                    <length>0.127</length>
                </cylinder>
            </geometry>
        </collision>
        <sensor name='fpr_contact' type='contact'>
            <update_rate>100.0</update_rate>
            <always_on>1</always_on>
            <contact>
                <collision>tool_inertia_collision</collision>
                <topic>/fpr_contact</topic>
            </contact>
            <plugin name='fpr_contact_sensor' filename='libfpr_contact_sensor.so'/>
            <plugin name="gazebo_ros_bumper" filename="libgazebo_ros_bumper.so">
                <ros>
                    <argument>bumper_states:=fpr_contact_gz</argument>
                </ros>
                <frameName>world</frameName>
            </plugin>
        </sensor>
        <gravity>1</gravity>
    </link>
    <link name="leg1">
        <pose>0.48408892449920654 0 0.38042344827836255 0 0.7853981633974483 0</pose>
        <inertial>
            <pose>0.094 0 0 0 -0 0</pose>
            <mass>0.073</mass>
            <inertia>
              <ixx>1.5707e-6</ixx>
              <ixy>0</ixy>
              <ixz>0</ixz>
              <iyy>0.035</iyy>
              <iyz>0</iyz>
              <izz>0.035</izz>
            </inertia>
        </inertial>
        <visual name="leg1_visual">
            <pose>0 0 0 0 -0 0</pose>
            <geometry>
                <mesh>
                    <scale>0.001 0.001 0.001</scale>
                    <uri>model://fpr_interaction/meshes/leg.stl</uri>
                </mesh>
            </geometry>
        </visual>
        <collision name='leg1_inertia_collision'>
            <pose>0 0 0 0 1.570796325 0</pose>
            <geometry>
                <cylinder>
                    <radius>0.005</radius>
                    <length>1.0</length>
                </cylinder>
            </geometry>
        </collision>
        <gravity>1</gravity>
    </link>
    <link name="leg2">
        <pose>-0.24204446224960316 0.419233306307 0.38042344827836255 0 0.7853981633974483 2.0943951023931953</pose>
        <inertial>
            <pose>0.094 0 0 0 -0 0</pose>
            <mass>0.073</mass>
            <inertia>
              <ixx>1.5707e-6</ixx>
              <ixy>0</ixy>
              <ixz>0</ixz>
              <iyy>0.035</iyy>
              <iyz>0</iyz>
              <izz>0.035</izz>
            </inertia>
        </inertial>
        <visual name="leg2_visual">
            <pose>0 0 0 0 -0 0</pose>
            <geometry>
                <mesh>
                    <scale>0.001 0.001 0.001</scale>
                    <uri>model://fpr_interaction/meshes/leg.stl</uri>
                </mesh>
            </geometry>
        </visual>
        <collision name='leg2_inertia_collision'>
            <pose>0 0 0 0 1.570796325 0</pose>
            <geometry>
                <cylinder>
                    <radius>0.005</radius>
                    <length>1.0</length>
                </cylinder>
            </geometry>
        </collision>
        <gravity>1</gravity>
    </link>
    <link name="leg3">
        <pose>-0.24204446224960316 -0.419233306307 0.38042344827836255 0 0.7853981633974483 -2.0943951023931953</pose>
        <inertial>
            <pose>0.094 0 0 0 -0 0</pose>
            <mass>0.073</mass>
            <inertia>
              <ixx>1.5707e-6</ixx>
              <ixy>0</ixy>
              <ixz>0</ixz>
              <iyy>0.035</iyy>
              <iyz>0</iyz>
              <izz>0.035</izz>
            </inertia>
        </inertial>
        <visual name="leg3_visual">
            <pose>0 0 0 0 -0 0</pose>
            <geometry>
                <mesh>
                    <scale>0.001 0.001 0.001</scale>
                    <uri>model://fpr_interaction/meshes/leg.stl</uri>
                </mesh>
            </geometry>
        </visual>
        <collision name='leg3_inertia_collision'>
            <pose>0 0 0 0 1.570796325 0</pose>
            <geometry>
                <cylinder>
                    <radius>0.005</radius>
                    <length>1.0</length>
                </cylinder>
            </geometry>
        </collision>
        <gravity>1</gravity>
    </link>
    <joint name="revolute_leg_1" type="revolute">
        <child>platform</child>
        <parent>leg1</parent>
        <pose>0.127 0 0</pose>
        <axis>
            <xyz>0 1 0</xyz>
        </axis>
    </joint>
    <joint name="revolute_leg_2" type="revolute">
        <child>platform</child>
        <parent>leg2</parent>
        <pose>-0.06349999999999997 0.10998522628062372 0</pose>
        <axis>
            <xyz>0.8660254037844387 0.4999999999999998 0</xyz>
        </axis>
    </joint>
    <joint name="revolute_leg_3" type="revolute">
        <child>platform</child>
        <parent>leg3</parent>
        <pose>-0.06349999999999997 -0.10998522628062372 0</pose>
        <axis>
            <xyz>0.8660254037844387 -0.4999999999999998 0</xyz>
        </axis>
    </joint>
    <plugin name="gazebo_ros_p3d" filename="libgazebo_ros_p3d.so">
        <ros>
          <namespace>FPR/Mocap</namespace>
        </ros>
        <body_name>platform</body_name>
        <update_rate>100</update_rate>
        <frame_name>world</frame_name>
    </plugin>
    <plugin name='fpr_init' filename='libfpr_init.so'/>
  </model>
</sdf>
